[2024-01-02T15:47:13.386+0000] {taskinstance.py:1957} INFO - Dependencies all met for dep_context=non-requeueable deps ti=<TaskInstance: snow_dag.is_snow_api_ready manual__2024-01-02T15:47:03.819825+00:00 [queued]>
[2024-01-02T15:47:13.401+0000] {taskinstance.py:1957} INFO - Dependencies all met for dep_context=requeueable deps ti=<TaskInstance: snow_dag.is_snow_api_ready manual__2024-01-02T15:47:03.819825+00:00 [queued]>
[2024-01-02T15:47:13.401+0000] {taskinstance.py:2171} INFO - Starting attempt 1 of 3
[2024-01-02T15:47:13.502+0000] {taskinstance.py:2192} INFO - Executing <Task(HttpSensor): is_snow_api_ready> on 2024-01-02 15:47:03.819825+00:00
[2024-01-02T15:47:13.507+0000] {standard_task_runner.py:60} INFO - Started process 127 to run task
[2024-01-02T15:47:13.511+0000] {standard_task_runner.py:87} INFO - Running: ['airflow', 'tasks', 'run', 'snow_dag', 'is_snow_api_ready', 'manual__2024-01-02T15:47:03.819825+00:00', '--job-id', '14', '--raw', '--subdir', 'DAGS_FOLDER/servicenow_dag.py', '--cfg-path', '/tmp/tmpx46zn9vy']
[2024-01-02T15:47:13.514+0000] {standard_task_runner.py:88} INFO - Job 14: Subtask is_snow_api_ready
[2024-01-02T15:47:13.646+0000] {task_command.py:423} INFO - Running <TaskInstance: snow_dag.is_snow_api_ready manual__2024-01-02T15:47:03.819825+00:00 [running]> on host e3b9753a290d
[2024-01-02T15:47:13.899+0000] {taskinstance.py:2481} INFO - Exporting env vars: AIRFLOW_CTX_DAG_OWNER='prady1900' AIRFLOW_CTX_DAG_ID='snow_dag' AIRFLOW_CTX_TASK_ID='is_snow_api_ready' AIRFLOW_CTX_EXECUTION_DATE='2024-01-02T15:47:03.819825+00:00' AIRFLOW_CTX_TRY_NUMBER='1' AIRFLOW_CTX_DAG_RUN_ID='manual__2024-01-02T15:47:03.819825+00:00'
[2024-01-02T15:47:13.900+0000] {http.py:130} INFO - Poking: api/now/table/incident
[2024-01-02T15:47:13.927+0000] {taskinstance.py:2699} ERROR - Task failed with exception
Traceback (most recent call last):
  File "/home/airflow/.local/lib/python3.8/site-packages/airflow/models/taskinstance.py", line 433, in _execute_task
    result = execute_callable(context=context, **execute_callable_kwargs)
  File "/home/airflow/.local/lib/python3.8/site-packages/airflow/sensors/base.py", line 263, in execute
    raise e
  File "/home/airflow/.local/lib/python3.8/site-packages/airflow/sensors/base.py", line 245, in execute
    poke_return = self.poke(context)
  File "/home/airflow/.local/lib/python3.8/site-packages/airflow/providers/http/sensors/http.py", line 148, in poke
    raise exc
  File "/home/airflow/.local/lib/python3.8/site-packages/airflow/providers/http/sensors/http.py", line 132, in poke
    response = hook.run(
  File "/home/airflow/.local/lib/python3.8/site-packages/airflow/providers/http/hooks/http.py", line 145, in run
    session = self.get_conn(headers)
  File "/home/airflow/.local/lib/python3.8/site-packages/airflow/providers/http/hooks/http.py", line 98, in get_conn
    conn = self.get_connection(self.http_conn_id)
  File "/home/airflow/.local/lib/python3.8/site-packages/airflow/hooks/base.py", line 82, in get_connection
    conn = Connection.get_connection_from_secrets(conn_id)
  File "/home/airflow/.local/lib/python3.8/site-packages/airflow/models/connection.py", line 479, in get_connection_from_secrets
    raise AirflowNotFoundException(f"The conn_id `{conn_id}` isn't defined")
airflow.exceptions.AirflowNotFoundException: The conn_id `snow_api_id` isn't defined
[2024-01-02T15:47:13.934+0000] {taskinstance.py:1138} INFO - Marking task as UP_FOR_RETRY. dag_id=snow_dag, task_id=is_snow_api_ready, execution_date=20240102T154703, start_date=20240102T154713, end_date=20240102T154713
[2024-01-02T15:47:14.032+0000] {standard_task_runner.py:107} ERROR - Failed to execute job 14 for task is_snow_api_ready (The conn_id `snow_api_id` isn't defined; 127)
[2024-01-02T15:47:14.046+0000] {local_task_job_runner.py:234} INFO - Task exited with return code 1
[2024-01-02T15:47:14.075+0000] {taskinstance.py:3281} INFO - 0 downstream tasks scheduled from follow-on schedule check
