[2024-01-02T15:51:18.618+0000] {taskinstance.py:1957} INFO - Dependencies all met for dep_context=non-requeueable deps ti=<TaskInstance: snow_dag.is_snow_api_ready scheduled__2024-01-01T00:00:00+00:00 [queued]>
[2024-01-02T15:51:18.631+0000] {taskinstance.py:1957} INFO - Dependencies all met for dep_context=requeueable deps ti=<TaskInstance: snow_dag.is_snow_api_ready scheduled__2024-01-01T00:00:00+00:00 [queued]>
[2024-01-02T15:51:18.631+0000] {taskinstance.py:2171} INFO - Starting attempt 3 of 3
[2024-01-02T15:51:18.733+0000] {taskinstance.py:2192} INFO - Executing <Task(HttpSensor): is_snow_api_ready> on 2024-01-01 00:00:00+00:00
[2024-01-02T15:51:18.738+0000] {standard_task_runner.py:60} INFO - Started process 218 to run task
[2024-01-02T15:51:18.742+0000] {standard_task_runner.py:87} INFO - Running: ['airflow', 'tasks', 'run', 'snow_dag', 'is_snow_api_ready', 'scheduled__2024-01-01T00:00:00+00:00', '--job-id', '19', '--raw', '--subdir', 'DAGS_FOLDER/servicenow_dag.py', '--cfg-path', '/tmp/tmpbkbd9cp7']
[2024-01-02T15:51:18.745+0000] {standard_task_runner.py:88} INFO - Job 19: Subtask is_snow_api_ready
[2024-01-02T15:51:18.906+0000] {task_command.py:423} INFO - Running <TaskInstance: snow_dag.is_snow_api_ready scheduled__2024-01-01T00:00:00+00:00 [running]> on host e3b9753a290d
[2024-01-02T15:51:19.085+0000] {taskinstance.py:2481} INFO - Exporting env vars: AIRFLOW_CTX_DAG_OWNER='prady1900' AIRFLOW_CTX_DAG_ID='snow_dag' AIRFLOW_CTX_TASK_ID='is_snow_api_ready' AIRFLOW_CTX_EXECUTION_DATE='2024-01-01T00:00:00+00:00' AIRFLOW_CTX_TRY_NUMBER='3' AIRFLOW_CTX_DAG_RUN_ID='scheduled__2024-01-01T00:00:00+00:00'
[2024-01-02T15:51:19.086+0000] {http.py:130} INFO - Poking: api/now/table/incident
[2024-01-02T15:51:19.112+0000] {taskinstance.py:2699} ERROR - Task failed with exception
Traceback (most recent call last):
  File "/home/airflow/.local/lib/python3.8/site-packages/airflow/models/taskinstance.py", line 433, in _execute_task
    result = execute_callable(context=context, **execute_callable_kwargs)
  File "/home/airflow/.local/lib/python3.8/site-packages/airflow/sensors/base.py", line 263, in execute
    raise e
  File "/home/airflow/.local/lib/python3.8/site-packages/airflow/sensors/base.py", line 245, in execute
    poke_return = self.poke(context)
  File "/home/airflow/.local/lib/python3.8/site-packages/airflow/providers/http/sensors/http.py", line 148, in poke
    raise exc
  File "/home/airflow/.local/lib/python3.8/site-packages/airflow/providers/http/sensors/http.py", line 132, in poke
    response = hook.run(
  File "/home/airflow/.local/lib/python3.8/site-packages/airflow/providers/http/hooks/http.py", line 145, in run
    session = self.get_conn(headers)
  File "/home/airflow/.local/lib/python3.8/site-packages/airflow/providers/http/hooks/http.py", line 98, in get_conn
    conn = self.get_connection(self.http_conn_id)
  File "/home/airflow/.local/lib/python3.8/site-packages/airflow/hooks/base.py", line 82, in get_connection
    conn = Connection.get_connection_from_secrets(conn_id)
  File "/home/airflow/.local/lib/python3.8/site-packages/airflow/models/connection.py", line 479, in get_connection_from_secrets
    raise AirflowNotFoundException(f"The conn_id `{conn_id}` isn't defined")
airflow.exceptions.AirflowNotFoundException: The conn_id `snow_api_id` isn't defined
[2024-01-02T15:51:19.119+0000] {taskinstance.py:1138} INFO - Marking task as FAILED. dag_id=snow_dag, task_id=is_snow_api_ready, execution_date=20240101T000000, start_date=20240102T155118, end_date=20240102T155119
[2024-01-02T15:51:19.219+0000] {standard_task_runner.py:107} ERROR - Failed to execute job 19 for task is_snow_api_ready (The conn_id `snow_api_id` isn't defined; 218)
[2024-01-02T15:51:19.237+0000] {local_task_job_runner.py:234} INFO - Task exited with return code 1
[2024-01-02T15:51:19.311+0000] {taskinstance.py:3281} INFO - 0 downstream tasks scheduled from follow-on schedule check
