[2024-01-04T13:48:49.736+0000] {taskinstance.py:1957} INFO - Dependencies all met for dep_context=non-requeueable deps ti=<TaskInstance: db_dg.insert_using_python_data scheduled__2024-01-03T00:00:00+00:00 [queued]>
[2024-01-04T13:48:49.749+0000] {taskinstance.py:1957} INFO - Dependencies all met for dep_context=requeueable deps ti=<TaskInstance: db_dg.insert_using_python_data scheduled__2024-01-03T00:00:00+00:00 [queued]>
[2024-01-04T13:48:49.750+0000] {taskinstance.py:2171} INFO - Starting attempt 4 of 6
[2024-01-04T13:48:49.875+0000] {taskinstance.py:2192} INFO - Executing <Task(PythonOperator): insert_using_python_data> on 2024-01-03 00:00:00+00:00
[2024-01-04T13:48:49.884+0000] {standard_task_runner.py:60} INFO - Started process 768 to run task
[2024-01-04T13:48:49.887+0000] {standard_task_runner.py:87} INFO - Running: ['airflow', 'tasks', 'run', 'db_dg', 'insert_using_python_data', 'scheduled__2024-01-03T00:00:00+00:00', '--job-id', '20', '--raw', '--subdir', 'DAGS_FOLDER/create_database_dag.py', '--cfg-path', '/tmp/tmpvmxupteg']
[2024-01-04T13:48:49.889+0000] {standard_task_runner.py:88} INFO - Job 20: Subtask insert_using_python_data
[2024-01-04T13:48:50.031+0000] {task_command.py:423} INFO - Running <TaskInstance: db_dg.insert_using_python_data scheduled__2024-01-03T00:00:00+00:00 [running]> on host 4a92eecc6669
[2024-01-04T13:48:50.178+0000] {taskinstance.py:2481} INFO - Exporting env vars: AIRFLOW_CTX_DAG_OWNER='prady1900' AIRFLOW_CTX_DAG_ID='db_dg' AIRFLOW_CTX_TASK_ID='insert_using_python_data' AIRFLOW_CTX_EXECUTION_DATE='2024-01-03T00:00:00+00:00' AIRFLOW_CTX_TRY_NUMBER='4' AIRFLOW_CTX_DAG_RUN_ID='scheduled__2024-01-03T00:00:00+00:00'
[2024-01-04T13:48:50.191+0000] {base.py:83} INFO - Using connection ID 'postgres_connect' for task execution.
[2024-01-04T13:48:50.266+0000] {base.py:83} INFO - Using connection ID 'postgres_connect' for task execution.
[2024-01-04T13:48:50.300+0000] {taskinstance.py:2699} ERROR - Task failed with exception
Traceback (most recent call last):
  File "/home/airflow/.local/lib/python3.8/site-packages/airflow/models/taskinstance.py", line 433, in _execute_task
    result = execute_callable(context=context, **execute_callable_kwargs)
  File "/home/airflow/.local/lib/python3.8/site-packages/airflow/operators/python.py", line 199, in execute
    return_value = self.execute_callable()
  File "/home/airflow/.local/lib/python3.8/site-packages/airflow/operators/python.py", line 216, in execute_callable
    return self.python_callable(*self.op_args, **self.op_kwargs)
  File "/opt/airflow/dags/create_database_dag.py", line 53, in insert_data_postg
    sql_stmt = str("insert into incident_new (impact,number,severity,priority,assignment_group,resolve_time,category) Values ({0},{1},{2},{3},{4},{5},{6}})").format(imp,number,sev,prio,av,res,cat)
ValueError: Single '}' encountered in format string
[2024-01-04T13:48:50.310+0000] {taskinstance.py:1138} INFO - Marking task as UP_FOR_RETRY. dag_id=db_dg, task_id=insert_using_python_data, execution_date=20240103T000000, start_date=20240104T134849, end_date=20240104T134850
[2024-01-04T13:48:50.392+0000] {standard_task_runner.py:107} ERROR - Failed to execute job 20 for task insert_using_python_data (Single '}' encountered in format string; 768)
[2024-01-04T13:48:50.425+0000] {local_task_job_runner.py:234} INFO - Task exited with return code 1
[2024-01-04T13:48:50.447+0000] {taskinstance.py:3281} INFO - 0 downstream tasks scheduled from follow-on schedule check
