[2024-01-04T10:31:28.692+0000] {taskinstance.py:1957} INFO - Dependencies all met for dep_context=non-requeueable deps ti=<TaskInstance: db_dg.insert_data_in_db manual__2024-01-04T07:00:44.090125+00:00 [queued]>
[2024-01-04T10:31:28.791+0000] {taskinstance.py:1957} INFO - Dependencies all met for dep_context=requeueable deps ti=<TaskInstance: db_dg.insert_data_in_db manual__2024-01-04T07:00:44.090125+00:00 [queued]>
[2024-01-04T10:31:28.791+0000] {taskinstance.py:2171} INFO - Starting attempt 3 of 5
[2024-01-04T10:31:28.940+0000] {taskinstance.py:2192} INFO - Executing <Task(PythonOperator): insert_data_in_db> on 2024-01-04 07:00:44.090125+00:00
[2024-01-04T10:31:28.944+0000] {standard_task_runner.py:60} INFO - Started process 1807 to run task
[2024-01-04T10:31:28.947+0000] {standard_task_runner.py:87} INFO - Running: ['airflow', 'tasks', 'run', 'db_dg', 'insert_data_in_db', 'manual__2024-01-04T07:00:44.090125+00:00', '--job-id', '73', '--raw', '--subdir', 'DAGS_FOLDER/create_database_dag.py', '--cfg-path', '/tmp/tmp6g59abo5']
[2024-01-04T10:31:28.949+0000] {standard_task_runner.py:88} INFO - Job 73: Subtask insert_data_in_db
[2024-01-04T10:31:29.154+0000] {task_command.py:423} INFO - Running <TaskInstance: db_dg.insert_data_in_db manual__2024-01-04T07:00:44.090125+00:00 [running]> on host 34fb0f920c20
[2024-01-04T10:31:29.310+0000] {taskinstance.py:2481} INFO - Exporting env vars: AIRFLOW_CTX_DAG_OWNER='prady1900' AIRFLOW_CTX_DAG_ID='db_dg' AIRFLOW_CTX_TASK_ID='insert_data_in_db' AIRFLOW_CTX_EXECUTION_DATE='2024-01-04T07:00:44.090125+00:00' AIRFLOW_CTX_TRY_NUMBER='3' AIRFLOW_CTX_DAG_RUN_ID='manual__2024-01-04T07:00:44.090125+00:00'
[2024-01-04T10:31:29.323+0000] {taskinstance.py:2699} ERROR - Task failed with exception
Traceback (most recent call last):
  File "/home/airflow/.local/lib/python3.8/site-packages/airflow/models/taskinstance.py", line 433, in _execute_task
    result = execute_callable(context=context, **execute_callable_kwargs)
  File "/home/airflow/.local/lib/python3.8/site-packages/airflow/operators/python.py", line 199, in execute
    return_value = self.execute_callable()
  File "/home/airflow/.local/lib/python3.8/site-packages/airflow/operators/python.py", line 216, in execute_callable
    return self.python_callable(*self.op_args, **self.op_kwargs)
  File "/opt/airflow/dags/create_database_dag.py", line 47, in insert_data_postg
    print(os.environ['TABLE_NAME'])
  File "/usr/local/lib/python3.8/os.py", line 675, in __getitem__
    raise KeyError(key) from None
KeyError: 'TABLE_NAME'
[2024-01-04T10:31:29.339+0000] {taskinstance.py:1138} INFO - Marking task as UP_FOR_RETRY. dag_id=db_dg, task_id=insert_data_in_db, execution_date=20240104T070044, start_date=20240104T103128, end_date=20240104T103129
[2024-01-04T10:31:29.433+0000] {standard_task_runner.py:107} ERROR - Failed to execute job 73 for task insert_data_in_db ('TABLE_NAME'; 1807)
[2024-01-04T10:31:29.441+0000] {local_task_job_runner.py:234} INFO - Task exited with return code 1
[2024-01-04T10:31:29.461+0000] {taskinstance.py:3281} INFO - 0 downstream tasks scheduled from follow-on schedule check
