[2024-01-04T10:34:05.723+0000] {taskinstance.py:1957} INFO - Dependencies all met for dep_context=non-requeueable deps ti=<TaskInstance: db_dg.insert_data_in_db manual__2024-01-04T07:00:44.090125+00:00 [queued]>
[2024-01-04T10:34:05.746+0000] {taskinstance.py:1957} INFO - Dependencies all met for dep_context=requeueable deps ti=<TaskInstance: db_dg.insert_data_in_db manual__2024-01-04T07:00:44.090125+00:00 [queued]>
[2024-01-04T10:34:05.747+0000] {taskinstance.py:2171} INFO - Starting attempt 5 of 7
[2024-01-04T10:34:05.869+0000] {taskinstance.py:2192} INFO - Executing <Task(PythonOperator): insert_data_in_db> on 2024-01-04 07:00:44.090125+00:00
[2024-01-04T10:34:05.875+0000] {standard_task_runner.py:60} INFO - Started process 1859 to run task
[2024-01-04T10:34:05.880+0000] {standard_task_runner.py:87} INFO - Running: ['airflow', 'tasks', 'run', 'db_dg', 'insert_data_in_db', 'manual__2024-01-04T07:00:44.090125+00:00', '--job-id', '75', '--raw', '--subdir', 'DAGS_FOLDER/create_database_dag.py', '--cfg-path', '/tmp/tmpwb5zkkoo']
[2024-01-04T10:34:05.883+0000] {standard_task_runner.py:88} INFO - Job 75: Subtask insert_data_in_db
[2024-01-04T10:34:06.065+0000] {task_command.py:423} INFO - Running <TaskInstance: db_dg.insert_data_in_db manual__2024-01-04T07:00:44.090125+00:00 [running]> on host 34fb0f920c20
[2024-01-04T10:34:06.433+0000] {taskinstance.py:2481} INFO - Exporting env vars: AIRFLOW_CTX_DAG_OWNER='prady1900' AIRFLOW_CTX_DAG_ID='db_dg' AIRFLOW_CTX_TASK_ID='insert_data_in_db' AIRFLOW_CTX_EXECUTION_DATE='2024-01-04T07:00:44.090125+00:00' AIRFLOW_CTX_TRY_NUMBER='5' AIRFLOW_CTX_DAG_RUN_ID='manual__2024-01-04T07:00:44.090125+00:00'
[2024-01-04T10:34:06.447+0000] {logging_mixin.py:188} INFO - accessing variable
[2024-01-04T10:34:06.447+0000] {taskinstance.py:2699} ERROR - Task failed with exception
Traceback (most recent call last):
  File "/home/airflow/.local/lib/python3.8/site-packages/airflow/models/taskinstance.py", line 433, in _execute_task
    result = execute_callable(context=context, **execute_callable_kwargs)
  File "/home/airflow/.local/lib/python3.8/site-packages/airflow/operators/python.py", line 199, in execute
    return_value = self.execute_callable()
  File "/home/airflow/.local/lib/python3.8/site-packages/airflow/operators/python.py", line 216, in execute_callable
    return self.python_callable(*self.op_args, **self.op_kwargs)
  File "/opt/airflow/dags/create_database_dag.py", line 48, in insert_data_postg
    print(os.getenv['TABLE_NAME'])
TypeError: 'function' object is not subscriptable
[2024-01-04T10:34:06.462+0000] {taskinstance.py:1138} INFO - Marking task as UP_FOR_RETRY. dag_id=db_dg, task_id=insert_data_in_db, execution_date=20240104T070044, start_date=20240104T103405, end_date=20240104T103406
[2024-01-04T10:34:06.589+0000] {standard_task_runner.py:107} ERROR - Failed to execute job 75 for task insert_data_in_db ('function' object is not subscriptable; 1859)
[2024-01-04T10:34:06.616+0000] {local_task_job_runner.py:234} INFO - Task exited with return code 1
[2024-01-04T10:34:06.635+0000] {taskinstance.py:3281} INFO - 0 downstream tasks scheduled from follow-on schedule check
