[2024-01-04T10:58:35.997+0000] {taskinstance.py:1957} INFO - Dependencies all met for dep_context=non-requeueable deps ti=<TaskInstance: db_dg.insert_data_in_db manual__2024-01-04T07:00:44.090125+00:00 [queued]>
[2024-01-04T10:58:36.017+0000] {taskinstance.py:1957} INFO - Dependencies all met for dep_context=requeueable deps ti=<TaskInstance: db_dg.insert_data_in_db manual__2024-01-04T07:00:44.090125+00:00 [queued]>
[2024-01-04T10:58:36.017+0000] {taskinstance.py:2171} INFO - Starting attempt 13 of 13
[2024-01-04T10:58:36.137+0000] {taskinstance.py:2192} INFO - Executing <Task(PythonOperator): insert_data_in_db> on 2024-01-04 07:00:44.090125+00:00
[2024-01-04T10:58:36.145+0000] {standard_task_runner.py:60} INFO - Started process 2170 to run task
[2024-01-04T10:58:36.149+0000] {standard_task_runner.py:87} INFO - Running: ['airflow', 'tasks', 'run', 'db_dg', 'insert_data_in_db', 'manual__2024-01-04T07:00:44.090125+00:00', '--job-id', '83', '--raw', '--subdir', 'DAGS_FOLDER/create_database_dag.py', '--cfg-path', '/tmp/tmpucdkoggp']
[2024-01-04T10:58:36.152+0000] {standard_task_runner.py:88} INFO - Job 83: Subtask insert_data_in_db
[2024-01-04T10:58:36.307+0000] {task_command.py:423} INFO - Running <TaskInstance: db_dg.insert_data_in_db manual__2024-01-04T07:00:44.090125+00:00 [running]> on host 34fb0f920c20
[2024-01-04T10:58:36.477+0000] {taskinstance.py:2481} INFO - Exporting env vars: AIRFLOW_CTX_DAG_OWNER='prady1900' AIRFLOW_CTX_DAG_ID='db_dg' AIRFLOW_CTX_TASK_ID='insert_data_in_db' AIRFLOW_CTX_EXECUTION_DATE='2024-01-04T07:00:44.090125+00:00' AIRFLOW_CTX_TRY_NUMBER='13' AIRFLOW_CTX_DAG_RUN_ID='manual__2024-01-04T07:00:44.090125+00:00'
[2024-01-04T10:58:36.516+0000] {logging_mixin.py:188} INFO - accessing variable
[2024-01-04T10:58:36.517+0000] {logging_mixin.py:188} INFO - None
[2024-01-04T10:58:36.517+0000] {taskinstance.py:2699} ERROR - Task failed with exception
Traceback (most recent call last):
  File "/home/airflow/.local/lib/python3.8/site-packages/airflow/models/taskinstance.py", line 433, in _execute_task
    result = execute_callable(context=context, **execute_callable_kwargs)
  File "/home/airflow/.local/lib/python3.8/site-packages/airflow/operators/python.py", line 199, in execute
    return_value = self.execute_callable()
  File "/home/airflow/.local/lib/python3.8/site-packages/airflow/operators/python.py", line 216, in execute_callable
    return self.python_callable(*self.op_args, **self.op_kwargs)
  File "/opt/airflow/dags/create_database_dag.py", line 51, in insert_data_postg
    stmt = meta.tables['incident_new'].insert().value(
KeyError: 'incident_new'
[2024-01-04T10:58:36.535+0000] {taskinstance.py:1138} INFO - Marking task as FAILED. dag_id=db_dg, task_id=insert_data_in_db, execution_date=20240104T070044, start_date=20240104T105835, end_date=20240104T105836
[2024-01-04T10:58:36.661+0000] {standard_task_runner.py:107} ERROR - Failed to execute job 83 for task insert_data_in_db ('incident_new'; 2170)
[2024-01-04T10:58:36.682+0000] {local_task_job_runner.py:234} INFO - Task exited with return code 1
[2024-01-04T10:58:36.701+0000] {taskinstance.py:3281} INFO - 0 downstream tasks scheduled from follow-on schedule check
