[2024-01-04T17:09:30.669+0000] {taskinstance.py:1957} INFO - Dependencies all met for dep_context=non-requeueable deps ti=<TaskInstance: db_dg.insert_using_python_data manual__2024-01-04T17:06:51.273139+00:00 [queued]>
[2024-01-04T17:09:31.363+0000] {taskinstance.py:1957} INFO - Dependencies all met for dep_context=requeueable deps ti=<TaskInstance: db_dg.insert_using_python_data manual__2024-01-04T17:06:51.273139+00:00 [queued]>
[2024-01-04T17:09:31.365+0000] {taskinstance.py:2171} INFO - Starting attempt 2 of 3
[2024-01-04T17:09:31.838+0000] {taskinstance.py:2192} INFO - Executing <Task(PythonOperator): insert_using_python_data> on 2024-01-04 17:06:51.273139+00:00
[2024-01-04T17:09:31.860+0000] {standard_task_runner.py:60} INFO - Started process 560 to run task
[2024-01-04T17:09:31.865+0000] {standard_task_runner.py:87} INFO - Running: ['airflow', 'tasks', 'run', 'db_dg', 'insert_using_python_data', 'manual__2024-01-04T17:06:51.273139+00:00', '--job-id', '47', '--raw', '--subdir', 'DAGS_FOLDER/create_database_dag.py', '--cfg-path', '/tmp/tmpqvtkevuf']
[2024-01-04T17:09:31.871+0000] {standard_task_runner.py:88} INFO - Job 47: Subtask insert_using_python_data
[2024-01-04T17:09:32.549+0000] {task_command.py:423} INFO - Running <TaskInstance: db_dg.insert_using_python_data manual__2024-01-04T17:06:51.273139+00:00 [running]> on host e2a9126be768
[2024-01-04T17:09:33.701+0000] {taskinstance.py:2481} INFO - Exporting env vars: AIRFLOW_CTX_DAG_OWNER='prady1900' AIRFLOW_CTX_DAG_ID='db_dg' AIRFLOW_CTX_TASK_ID='insert_using_python_data' AIRFLOW_CTX_EXECUTION_DATE='2024-01-04T17:06:51.273139+00:00' AIRFLOW_CTX_TRY_NUMBER='2' AIRFLOW_CTX_DAG_RUN_ID='manual__2024-01-04T17:06:51.273139+00:00'
[2024-01-04T17:09:33.717+0000] {base.py:83} INFO - Using connection ID 'postgres_connect' for task execution.
[2024-01-04T17:09:33.877+0000] {taskinstance.py:2699} ERROR - Task failed with exception
Traceback (most recent call last):
  File "/home/airflow/.local/lib/python3.8/site-packages/airflow/models/taskinstance.py", line 433, in _execute_task
    result = execute_callable(context=context, **execute_callable_kwargs)
  File "/home/airflow/.local/lib/python3.8/site-packages/airflow/operators/python.py", line 199, in execute
    return_value = self.execute_callable()
  File "/home/airflow/.local/lib/python3.8/site-packages/airflow/operators/python.py", line 216, in execute_callable
    return self.python_callable(*self.op_args, **self.op_kwargs)
  File "/opt/airflow/dags/create_database_dag.py", line 51, in insert_data_postg
    df_inc = pd.read_csv('./data/incidents.csv')
  File "/home/airflow/.local/lib/python3.8/site-packages/pandas/io/parsers/readers.py", line 912, in read_csv
    return _read(filepath_or_buffer, kwds)
  File "/home/airflow/.local/lib/python3.8/site-packages/pandas/io/parsers/readers.py", line 577, in _read
    parser = TextFileReader(filepath_or_buffer, **kwds)
  File "/home/airflow/.local/lib/python3.8/site-packages/pandas/io/parsers/readers.py", line 1407, in __init__
    self._engine = self._make_engine(f, self.engine)
  File "/home/airflow/.local/lib/python3.8/site-packages/pandas/io/parsers/readers.py", line 1661, in _make_engine
    self.handles = get_handle(
  File "/home/airflow/.local/lib/python3.8/site-packages/pandas/io/common.py", line 859, in get_handle
    handle = open(
FileNotFoundError: [Errno 2] No such file or directory: './data/incidents.csv'
[2024-01-04T17:09:33.968+0000] {taskinstance.py:1138} INFO - Marking task as UP_FOR_RETRY. dag_id=db_dg, task_id=insert_using_python_data, execution_date=20240104T170651, start_date=20240104T170930, end_date=20240104T170933
[2024-01-04T17:09:34.217+0000] {standard_task_runner.py:107} ERROR - Failed to execute job 47 for task insert_using_python_data ([Errno 2] No such file or directory: './data/incidents.csv'; 560)
[2024-01-04T17:09:34.259+0000] {local_task_job_runner.py:234} INFO - Task exited with return code 1
[2024-01-04T17:09:34.331+0000] {taskinstance.py:3281} INFO - 0 downstream tasks scheduled from follow-on schedule check
